#VRML_SIM R2022b utf8

EXTERNPROTO "https://raw.githubusercontent.com/cyberbotics/webots/R2022b/projects/objects/backgrounds/protos/TexturedBackground.proto"
EXTERNPROTO "https://raw.githubusercontent.com/cyberbotics/webots/R2022b/projects/objects/backgrounds/protos/TexturedBackgroundLight.proto"
EXTERNPROTO "https://raw.githubusercontent.com/cyberbotics/webots/R2022b/projects/objects/floors/protos/RectangleArena.proto"

WorldInfo {
}
Viewpoint {
  orientation 0.13195169952746588 -0.057233743146101114 -0.9896024694983836 3.952488848421912
  position 0.7111362762988493 -0.727623056751777 0.37105938336487443
}
TexturedBackground {
}
TexturedBackgroundLight {
}
RectangleArena {
  rotation 0 1 0 0
}
Robot {
  translation -5.179522349861464e-10 2.6002651813753687e-11 -0.00018445071496458326
  rotation 0.488560232873875 -0.8725301707183541 6.3580486687977304e-06 7.020672862507294e-05
  children [
    DEF Body Transform {
      translation 0 0 0.045
      rotation 0 1 0 0
      children [
        Shape {
          appearance PBRAppearance {
            baseColor 0.333333 0.666667 1
            roughness 1
            metalness 0
          }
          geometry Cylinder {
            height 0.08
            radius 0.045
          }
        }
      ]
    }
    HingeJoint {
      jointParameters HingeJointParameters {
        position 17.080055710966608
        anchor 0.045 0 0.025
      }
      device [
        RotationalMotor {
          name "motor_1"
        }
      ]
      endPoint Solid {
        translation 0.045 0 0.025
        rotation -0.705216996102061 0.07829062846498958 -0.7046556363950709 2.9852061638020335
        children [
          DEF wheel Shape {
            appearance PBRAppearance {
              baseColor 1 0 0
              roughness 1
              metalness 0
            }
            geometry Cylinder {
              height 0.01
              radius 0.025
            }
          }
        ]
        boundingObject USE wheel
        physics DEF wheel_physics Physics {
        }
      }
    }
    HingeJoint {
      jointParameters HingeJointParameters {
        position 16.638079746405413
        anchor -0.045 0 0.025
      }
      device [
        RotationalMotor {
          name "motor_2"
        }
      ]
      endPoint Solid {
        translation -0.045 0 0.025
        rotation -0.7052169960416491 0.07829062955245736 -0.7046556363347082 2.9852061616386476
        children [
          USE wheel
        ]
        name "solid(1)"
        boundingObject USE wheel
        physics USE wheel_physics
      }
    }
    DEF eye_left Solid {
      translation 0.015 -0.045 0.07
      children [
        DEF eye Shape {
          appearance PBRAppearance {
            baseColor 1 0 0
            roughness 1
            metalness 0
          }
          geometry Box {
            size 0.01 0.005 0.01
          }
        }
      ]
      name "solid(2)"
    }
    DEF eye_right Solid {
      translation -0.015 -0.045 0.07
      children [
        USE eye
      ]
      name "solid(3)"
    }
  ]
  boundingObject USE Body
  physics Physics {
  }
  controller "drive_my_robot"
}
